<?xml version="1.0" ?>

<robot name="slip">

    <!-- Base -->
    <link name="base">
        <inertial>
            <mass value="20"/>
            <origin xyz="0.0 0.0 0.0"/>
            <inertia
                ixx="0.168459"
                ixy="0.000124"
                ixz="0.006493"
                iyy="0.101358"
                iyz="0.000278"
                izz="0.091754" />
        </inertial>
        <visual>
            <geometry>
                <!-- <sphere radius="0.125"/> -->
                <box size="0.15 0.3 0.35"/>
            </geometry>
            <origin rpy="0.0 0.0 0.0" xyz="0.0 0.0 0.0"/>
        </visual>
        <collision>
            <geometry>
                <!-- <sphere radius="0.125"/> -->
                <box size="0.15 0.3 0.35"/>
            </geometry>
            <origin rpy="0 0 0" xyz="0 0 0"/>
        </collision>
    </link>

    <!-- Right Leg -->
    <link name="right_hip_roll">  
        <inertial>
            <mass value="1.0"/>
        </inertial>
    </link>
    <joint name="right_roll" type="revolute">
        <parent link="base"/>
        <child link="right_hip_roll"/>
        <origin xyz="0 -0.1 -0.15"/>
        <axis xyz="1 0 0"/>
        <limit effort="144" velocity="10.0" lower="-0.785" upper="0.785"/>
    </joint>
    <link name="right_hip_pitch">
        <inertial>
            <mass value="1.0"/>
        </inertial>
        <visual>
            <origin rpy="0 1.571 0" xyz="0.175 0 0"/>
            <geometry>
                <cylinder radius="0.05" length="0.25"/>
            </geometry>
            <material name="right_hip_pitch_mat">
                <color rgba="0 0 0.7 1"/>
            </material>
        </visual>
    </link>
    <joint name="right_pitch" type="revolute">
        <parent link="right_hip_roll"/>
        <child link="right_hip_pitch"/>
        <origin xyz="0 0 0"/>
        <axis xyz="0 1 0"/>
        <limit effort="144" velocity="10.0" lower="0.785" upper="2.356"/>
    </joint>
    <link name="right_foot">
        <inertial>
            <mass value="0.5"/>
            <origin xyz="0. 0.0 0.0"/>
            <inertia ixx="0.5" ixy="0.5" ixz="0.5" iyy="0.5" iyz="0.5" izz="0.5"/>
        </inertial>
        <visual>
            <geometry>
                <sphere radius="0.05"/>
            </geometry>
            <material name="right_foot_mat">
                <color rgba="0. 0. 0.7 1"/>
            </material>
            <origin rpy="0.0 0.0 0.0" xyz="0.0 0.0 0.0"/>
        </visual>
        <collision>
            <geometry>
                <sphere radius="0.05"/>
            </geometry>
            <origin rpy="0 0 0" xyz="0 0 0"/>
        </collision>
    </link>
    <joint name="right_leg" type="prismatic">
        <parent link="right_hip_pitch"/>
        <child link="right_foot"/>
        <origin xyz="0 0 0"/>
        <axis xyz="1 0 0"/>
        <limit effort="1000" velocity="20.0" lower="0.3" upper="0.6"/>
    </joint>



    <!-- Left Leg -->
    <link name="left_hip_roll">  
        <inertial>
            <mass value="1.0"/>
        </inertial>
    </link>
    <joint name="left_roll" type="revolute">
        <parent link="base"/>
        <child link="left_hip_roll"/>
        <origin xyz="0 0.1 -0.15"/>
        <axis xyz="1 0 0"/>
        <limit effort="144" velocity="10.0" lower="-0.785" upper="0.785"/>
    </joint>
    <link name="left_hip_pitch">
        <inertial>
            <mass value="1.0"/>
        </inertial>
        <visual>
            <origin rpy="0 1.571 0" xyz="0.175 0 0"/>
            <geometry>
                <cylinder radius="0.05" length="0.25"/>
            </geometry>
            <material name="left_hip_pitch_mat">
                <color rgba="0.7 0 0 1"/>
            </material>
        </visual>
    </link>
    <joint name="left_pitch" type="revolute">
        <parent link="left_hip_roll"/>
        <child link="left_hip_pitch"/>
        <origin xyz="0 0 0"/>
        <axis xyz="0 1 0"/>
        <limit effort="144" velocity="10.0" lower="0.785" upper="2.356"/>
    </joint>

    <link name="left_foot">
        <inertial>
            <mass value="0.5"/>
            <origin xyz="0. 0.0 0.0"/>
            <inertia ixx="0.5" ixy="0.5" ixz="0.5" iyy="0.5" iyz="0.5" izz="0.5"/>
        </inertial>
        <visual>
            <geometry>
                <sphere radius="0.05"/>
            </geometry>
            <material name="left_foot_mat">
                <color rgba="0.7 0 0 1"/>
            </material>
        </visual>
        <collision>
            <geometry>
                <sphere radius="0.05"/>
            </geometry>
            <origin rpy="0 0 0" xyz="0 0 0"/>
        </collision>
    </link>
    <joint name="left_leg" type="prismatic">
        <parent link="left_hip_pitch"/>
        <child link="left_foot"/>
        <origin xyz="0 0 0"/>
        <axis xyz="1 0 0"/>
        <limit effort="1000" velocity="20.0" lower="0.3" upper="0.6"/>
    </joint>



</robot>
